Starting training on cx3-20-2.cx3.hpc.ic.ac.uk at Fri  6 Jun 10:38:22 BST 2025
Using config: configs/cifar/round_6_06_06/config_brainit_5_5.json
Traceback (most recent call last):
  File "/rds/general/user/psp20/home/Brain-Network/source/train.py", line 360, in main
    config, debug = parse_args()
    ^^^^^^^^^^^^^
ValueError: too many values to unpack (expected 2)

During handling of the above exception, another exception occurred:

Traceback (most recent call last):
  File "/rds/general/user/psp20/home/Brain-Network/source/train.py", line 546, in <module>
    main()
  File "/rds/general/user/psp20/home/Brain-Network/source/train.py", line 539, in main
    logger.exception("Error occured")
    ^^^^^^
UnboundLocalError: cannot access local variable 'logger' where it is not associated with a value
Finished at Fri  6 Jun 10:39:35 BST 2025
Clean up
mv: cannot stat 'job_logs/train.err': No such file or directory

====================================
CPU Time used: 00:00:00
CPU Percent: 0%
Memory usage: 33504kb
Approx Power usage: 0.0
Walltime usage: 00:01:25

====================================
